Workbook

Sheet asset_config
A1: OPT_NAME | B1: Ticker | C1: LONG_COMP_NAME | D1: CRNCY | E1: COUNTRY_ISO | F1: H_U | G1: Duration | H1: L1_CLASS | I1: L2_CLASS | J1: 5Y_GEO | K1: 5Y_ARI | L1: 10Y_GEO | M1: 10Y_ARI | N1: VOL | O1: PORT | P1: BMK | Q1: BMK_W
A2: {=TRANSPOSE(timeseries!B1:G1)} -> EUR Cash | F2: U | J2: =INDEX([1]Service_Arith_Geo!C:C, MATCH($A2, [1]Service_Arith_Geo!$B:$B, 0)) -> 0.019954589 | K2: =INDEX([1]Service_Arith_Geo!F:F, MATCH($A2, [1]Service_Arith_Geo!$B:$B, 0)) -> 0.019991501 | L2: =INDEX([1]Service_Arith_Geo!D:D, MATCH($A2, [1]Service_Arith_Geo!$B:$B, 0)) -> 0.018946772 | M2: =INDEX([1]Service_Arith_Geo!G:G, MATCH($A2, [1]Service_Arith_Geo!$B:$B, 0)) -> 0.018984656 | N2: =SQRT(INDEX(cov!$B$2:$G$7,MATCH($A2,cov!$A$2:$A$7,0),MATCH($A2,cov!$A$2:$A$7,0))) -> 0.00881529 | O2: Y | P2: Y | Q2: 0.1
A3: EMU Bond All MaturityU | F3: U | J3: =INDEX([1]Service_Arith_Geo!C:C, MATCH($A3, [1]Service_Arith_Geo!$B:$B, 0)) -> 0.035680264 | K3: =INDEX([1]Service_Arith_Geo!F:F, MATCH($A3, [1]Service_Arith_Geo!$B:$B, 0)) -> 0.036827392 | L3: =INDEX([1]Service_Arith_Geo!D:D, MATCH($A3, [1]Service_Arith_Geo!$B:$B, 0)) -> 0.03494341 | M3: =INDEX([1]Service_Arith_Geo!G:G, MATCH($A3, [1]Service_Arith_Geo!$B:$B, 0)) -> 0.036120725 | N3: =SQRT(INDEX(cov!$B$2:$G$7,MATCH($A3,cov!$A$2:$A$7,0),MATCH($A3,cov!$A$2:$A$7,0))) -> 0.0491427 | O3: Y | P3: Y | Q3: 0.1
A4: Barclays Global TreasuryH | F4: H | J4: =INDEX([1]Service_Arith_Geo!C:C, MATCH($A4, [1]Service_Arith_Geo!$B:$B, 0)) -> 0.031236986 | K4: =INDEX([1]Service_Arith_Geo!F:F, MATCH($A4, [1]Service_Arith_Geo!$B:$B, 0)) -> 0.031939742 | L4: =INDEX([1]Service_Arith_Geo!D:D, MATCH($A4, [1]Service_Arith_Geo!$B:$B, 0)) -> 0.032076044 | M4: =INDEX([1]Service_Arith_Geo!G:G, MATCH($A4, [1]Service_Arith_Geo!$B:$B, 0)) -> 0.032797294 | N4: =SQRT(INDEX(cov!$B$2:$G$7,MATCH($A4,cov!$A$2:$A$7,0),MATCH($A4,cov!$A$2:$A$7,0))) -> 0.038464093 | O4: Y | P4: Y | Q4: 0.1
A5: World EquityU | F5: U | J5: =INDEX([1]Service_Arith_Geo!C:C, MATCH($A5, [1]Service_Arith_Geo!$B:$B, 0)) -> 0.064834196 | K5: =INDEX([1]Service_Arith_Geo!F:F, MATCH($A5, [1]Service_Arith_Geo!$B:$B, 0)) -> 0.074823611 | L5: =INDEX([1]Service_Arith_Geo!D:D, MATCH($A5, [1]Service_Arith_Geo!$B:$B, 0)) -> 0.06658951 | M5: =INDEX([1]Service_Arith_Geo!G:G, MATCH($A5, [1]Service_Arith_Geo!$B:$B, 0)) -> 0.076841804 | N5: =SQRT(INDEX(cov!$B$2:$G$7,MATCH($A5,cov!$A$2:$A$7,0),MATCH($A5,cov!$A$2:$A$7,0))) -> 0.14501844 | O5: Y | P5: Y | Q5: 0.3
A6: Global Private DebtH | F6: H | J6: =INDEX([1]Service_Arith_Geo!C:C, MATCH($A6, [1]Service_Arith_Geo!$B:$B, 0)) -> 0.063317389 | K6: =INDEX([1]Service_Arith_Geo!F:F, MATCH($A6, [1]Service_Arith_Geo!$B:$B, 0)) -> 0.066978814 | L6: =INDEX([1]Service_Arith_Geo!D:D, MATCH($A6, [1]Service_Arith_Geo!$B:$B, 0)) -> 0.062922814 | M6: =INDEX([1]Service_Arith_Geo!G:G, MATCH($A6, [1]Service_Arith_Geo!$B:$B, 0)) -> 0.066680593 | N6: =SQRT(INDEX(cov!$B$2:$G$7,MATCH($A6,cov!$A$2:$A$7,0),MATCH($A6,cov!$A$2:$A$7,0))) -> 0.087796722 | O6: Y | P6: Y | Q6: 0.2
A7: EU Private CreditH | F7: H | J7: =INDEX([1]Service_Arith_Geo!C:C, MATCH($A7, [1]Service_Arith_Geo!$B:$B, 0)) -> 0.049326365 | K7: =INDEX([1]Service_Arith_Geo!F:F, MATCH($A7, [1]Service_Arith_Geo!$B:$B, 0)) -> 0.052448074 | L7: =INDEX([1]Service_Arith_Geo!D:D, MATCH($A7, [1]Service_Arith_Geo!$B:$B, 0)) -> 0.052363144 | M7: =INDEX([1]Service_Arith_Geo!G:G, MATCH($A7, [1]Service_Arith_Geo!$B:$B, 0)) -> 0.055567003 | N7: =SQRT(INDEX(cov!$B$2:$G$7,MATCH($A7,cov!$A$2:$A$7,0),MATCH($A7,cov!$A$2:$A$7,0))) -> 0.081067987 | O7: Y | P7: Y | Q7: 0.2

Sheet A
A1: -1 | B1: -1 | C1: 0 | D1: 0 | E1: 0 | F1: 0 | G1: 0 | H1: 0 | I1: 0 | J1: 0 | K1: 0 | L1: 0 | M1: 0 | N1: 0 | O1: 0 | P1: 0 | Q1: 0 | R1: 0
A2: 1 | B2: 1 | C2: 0 | D2: 0 | E2: 0 | F2: 0 | G2: 0 | H2: 0 | I2: 0 | J2: 0 | K2: 0 | L2: 0 | M2: 0 | N2: 0 | O2: 0 | P2: 0 | Q2: 0 | R2: 0
A3: 0 | B3: 0 | C3: -1 | D3: 0 | E3: 0 | F3: 0 | G3: 0 | H3: 0 | I3: 0 | J3: 0 | K3: 0 | L3: 0 | M3: 0 | N3: 0 | O3: 0 | P3: 0 | Q3: 0 | R3: 0
A4: 0 | B4: 0 | C4: 1 | D4: 0 | E4: 0 | F4: 0 | G4: 0 | H4: 0 | I4: 0 | J4: 0 | K4: 0 | L4: 0 | M4: 0 | N4: 0 | O4: 0 | P4: 0 | Q4: 0 | R4: 0
A5: 0 | B5: 0 | C5: 0 | D5: -1 | E5: -1 | F5: 0 | G5: 0 | H5: 0 | I5: 0 | J5: 0 | K5: 0 | L5: 0 | M5: 0 | N5: 0 | O5: 0 | P5: 0 | Q5: 0 | R5: 0
A6: 0 | B6: 0 | C6: 0 | D6: 1 | E6: 1 | F6: 0 | G6: 0 | H6: 0 | I6: 0 | J6: 0 | K6: 0 | L6: 0 | M6: 0 | N6: 0 | O6: 0 | P6: 0 | Q6: 0 | R6: 0
A7: 0 | B7: 0 | C7: 0 | D7: 0 | E7: 0 | F7: -1 | G7: -1 | H7: 0 | I7: 0 | J7: 0 | K7: 0 | L7: 0 | M7: 0 | N7: 0 | O7: 0 | P7: 0 | Q7: 0 | R7: 0
A8: 0 | B8: 0 | C8: 0 | D8: 0 | E8: 0 | F8: 1 | G8: 1 | H8: 0 | I8: 0 | J8: 0 | K8: 0 | L8: 0 | M8: 0 | N8: 0 | O8: 0 | P8: 0 | Q8: 0 | R8: 0
A9: 0 | B9: 0 | C9: 0 | D9: 0 | E9: 0 | F9: 0 | G9: 0 | H9: -1 | I9: 0 | J9: 0 | K9: 0 | L9: 0 | M9: 0 | N9: 0 | O9: 0 | P9: 0 | Q9: 0 | R9: 0
A10: 0 | B10: 0 | C10: 0 | D10: 0 | E10: 0 | F10: 0 | G10: 0 | H10: 1 | I10: 0 | J10: 0 | K10: 0 | L10: 0 | M10: 0 | N10: 0 | O10: 0 | P10: 0 | Q10: 0 | R10: 0
A11: 0 | B11: 0 | C11: 0 | D11: 0 | E11: 0 | F11: 0 | G11: 0 | H11: 0 | I11: -1 | J11: 0 | K11: 0 | L11: 0 | M11: 0 | N11: 0 | O11: 0 | P11: 0 | Q11: 0 | R11: 0
A12: 0 | B12: 0 | C12: 0 | D12: 0 | E12: 0 | F12: 0 | G12: 0 | H12: 0 | I12: 1 | J12: 0 | K12: 0 | L12: 0 | M12: 0 | N12: 0 | O12: 0 | P12: 0 | Q12: 0 | R12: 0
... A21: 0 | B21: 0 | C21: 0 | D21: 0 | E21: 0 | F21: 0 | G21: 0 | H21: 0 | I21: 0 | J21: 0 | K21: 0 | L21: 0 | M21: 0 | N21: 0 | O21: 0 | P21: 0 | Q21: 0 | R21: -1

Sheet B
A1: =-asset_config!#REF! -> #REF!
A2: =-A1 -> #REF!
A3: =-asset_config!#REF! -> #REF!
A4: =-A3 -> #REF!
A5: =-asset_config!#REF! -> #REF!
A6: =-A5 -> #REF!
A7: =-asset_config!#REF! -> #REF!
A8: =-A7 -> #REF!
A9: =-asset_config!#REF! -> #REF!
A10: =-A9 -> #REF!
A11: =-asset_config!#REF! -> #REF!
A12: =-A11 -> #REF!
A13: =-asset_config!#REF! -> #REF!
A14: =-A13 -> #REF!
A15: =-asset_config!#REF! -> #REF!
A16: =-A15 -> #REF!
A17: =-asset_config!#REF! -> #REF!
A18: =-A17 -> #REF!
A19: =-asset_config!#REF! -> #REF!
A20: =-A19 -> #REF!
A21: 0

Sheet timeseries
A1: Dates | B1: EUR Cash | C1: EMU Bond All MaturityU | D1: Barclays Global TreasuryH | E1: World EquityU | F1: Global Private DebtH | G1: EU Private CreditH
A2: 37802 | B2: 0.0073383518 | C2: 0.018780777 | D2: 0.016724759 | E2: -0.087251853 | F2: 0.0032875 | G2: -0.002
A3: 37894 | B3: 0.0067323234 | C3: 0.022617535 | D3: 0.01898688 | E3: 0.10981004 | F3: 0.00301375 | G3: 0.011
A4: 37986 | B4: 0.005526079 | C4: 0.001749503 | D4: -0.0057961635 | E4: 0.035343916 | F4: 0.002711 | G4: 0.018
A5: 38077 | B5: 0.0055774022 | C5: -0.0037012781 | D5: 0.0018690478 | E5: 0.057519873 | F5: 0.00284975 | G5: 0.011
A6: 38168 | B6: 0.0056166291 | C6: 0.029600709 | D6: 0.021660417 | E6: 0.049468947 | F6: 0.00236375 | G6: 0.025
A7: 38260 | B7: 0.0049279535 | C7: -0.0096203144 | D7: -0.013039358 | E7: 0.018175848 | F7: 0.0018745 | G7: 0.014
A8: 38352 | B8: 0.0054811339 | C8: 0.027353842 | D8: 0.026835221 | E8: -0.028740077 | F8: 0.00081675 | G8: 0.007
A9: 38442 | B9: 0.005625695 | C9: 0.028431941 | D9: 0.017205677 | E9: 0.027147435 | F9: -0.00044425 | G9: 0.007
A10: 38533 | B10: 0.0054821946 | C10: 0.012928544 | D10: 0.0071056846 | E10: 0.033775089 | F10: 0.032584652 | G10: 0.022
A11: 38625 | B11: 0.005535688 | C11: 0.03802592 | D11: 0.029363221 | E11: 0.075423127 | F11: 0.048215036 | G11: 0.013
A12: 38716 | B12: 0.00532864 | C12: 0.0044444835 | D12: -0.0038109313 | E12: 0.07693701 | F12: 0.052206757 | G12: 0.011
A13: 38807 | B13: 0.0054326571 | C13: -0.0031512053 | D13: 0.0037825217 | E13: 0.046080331 | F13: 0.052010773 | G13: 0.013
... A92: 46022 | B92: 0.0053644628 | C92: -0.0019933086 | D92: 0.0016174644 | E92: 0.077634005 | F92: 0.043725672 | G92: 0.007
A93: 46112 | B93: 0.0057247445 | C93: 0.0029061383 | D93: 0.0016759174 | E93: 0.030086307 | F93: 0.034996761
A94: 46203 | B94: 0.0053511176 | C94: -0.0060748957 | D94: -0.0065869539 | E94: -0.019646898 | F94: 0.010917526
A95: 46295 | B95: 0.0058696701 | C95: 0.01828694 | D95: 0.007126777 | E95: 0.1505949 | F95: -0.00357625

Sheet cov
B1: {=TRANSPOSE(_xlfn.ANCHORARRAY(A2))} -> EUR Cash | C1: EMU Bond All MaturityU | D1: Barclays Global TreasuryH | E1: World EquityU | F1: Global Private DebtH | G1: EU Private CreditH
A2: {=TRANSPOSE(timeseries!B1:G1)} -> EUR Cash | B2: =_xlfn.COVARIANCE.S(INDEX(timeseries!$B$2:$G$95,,MATCH($A2,timeseries!$B$1:$G$1,0)),INDEX(timeseries!$B$2:$G$95,,MATCH(B$1,timeseries!$B$1:$G$1,0)))*4 -> 7.7709338e-05 | C2: =_xlfn.COVARIANCE.S(INDEX(timeseries!$B$2:$G$95,,MATCH($A2,timeseries!$B$1:$G$1,0)),INDEX(timeseries!$B$2:$G$95,,MATCH(C$1,timeseries!$B$1:$G$1,0)))*4 -> 8.7621516e-05 | D2: =_xlfn.COVARIANCE.S(INDEX(timeseries!$B$2:$G$95,,MATCH($A2,timeseries!$B$1:$G$1,0)),INDEX(timeseries!$B$2:$G$95,,MATCH(D$1,timeseries!$B$1:$G$1,0)))*4 -> 0.00010271235 | E2: =_xlfn.COVARIANCE.S(INDEX(timeseries!$B$2:$G$95,,MATCH($A2,timeseries!$B$1:$G$1,0)),INDEX(timeseries!$B$2:$G$95,,MATCH(E$1,timeseries!$B$1:$G$1,0)))*4 -> -0.0002691238 | F2: =_xlfn.COVARIANCE.S(INDEX(timeseries!$B$2:$G$95,,MATCH($A2,timeseries!$B$1:$G$1,0)),INDEX(timeseries!$B$2:$G$95,,MATCH(F$1,timeseries!$B$1:$G$1,0)))*4 -> -0.00014418609 | G2: =_xlfn.COVARIANCE.S(INDEX(timeseries!$B$2:$G$95,,MATCH($A2,timeseries!$B$1:$G$1,0)),INDEX(timeseries!$B$2:$G$95,,MATCH(G$1,timeseries!$B$1:$G$1,0)))*4 -> -0.00026665598
A3: EMU Bond All MaturityU | B3: =_xlfn.COVARIANCE.S(INDEX(timeseries!$B$2:$G$95,,MATCH($A3,timeseries!$B$1:$G$1,0)),INDEX(timeseries!$B$2:$G$95,,MATCH(B$1,timeseries!$B$1:$G$1,0)))*4 -> 8.7621516e-05 | C3: =_xlfn.COVARIANCE.S(INDEX(timeseries!$B$2:$G$95,,MATCH($A3,timeseries!$B$1:$G$1,0)),INDEX(timeseries!$B$2:$G$95,,MATCH(C$1,timeseries!$B$1:$G$1,0)))*4 -> 0.002415005 | D3: =_xlfn.COVARIANCE.S(INDEX(timeseries!$B$2:$G$95,,MATCH($A3,timeseries!$B$1:$G$1,0)),INDEX(timeseries!$B$2:$G$95,,MATCH(D$1,timeseries!$B$1:$G$1,0)))*4 -> 0.0016895151 | E3: =_xlfn.COVARIANCE.S(INDEX(timeseries!$B$2:$G$95,,MATCH($A3,timeseries!$B$1:$G$1,0)),INDEX(timeseries!$B$2:$G$95,,MATCH(E$1,timeseries!$B$1:$G$1,0)))*4 -> 0.00013365517 | F3: =_xlfn.COVARIANCE.S(INDEX(timeseries!$B$2:$G$95,,MATCH($A3,timeseries!$B$1:$G$1,0)),INDEX(timeseries!$B$2:$G$95,,MATCH(F$1,timeseries!$B$1:$G$1,0)))*4 -> -0.00073218725 | G3: =_xlfn.COVARIANCE.S(INDEX(timeseries!$B$2:$G$95,,MATCH($A3,timeseries!$B$1:$G$1,0)),INDEX(timeseries!$B$2:$G$95,,MATCH(G$1,timeseries!$B$1:$G$1,0)))*4 -> -0.00095990114
A4: Barclays Global TreasuryH | B4: =_xlfn.COVARIANCE.S(INDEX(timeseries!$B$2:$G$95,,MATCH($A4,timeseries!$B$1:$G$1,0)),INDEX(timeseries!$B$2:$G$95,,MATCH(B$1,timeseries!$B$1:$G$1,0)))*4 -> 0.00010271235 | C4: =_xlfn.COVARIANCE.S(INDEX(timeseries!$B$2:$G$95,,MATCH($A4,timeseries!$B$1:$G$1,0)),INDEX(timeseries!$B$2:$G$95,,MATCH(C$1,timeseries!$B$1:$G$1,0)))*4 -> 0.0016895151 | D4: =_xlfn.COVARIANCE.S(INDEX(timeseries!$B$2:$G$95,,MATCH($A4,timeseries!$B$1:$G$1,0)),INDEX(timeseries!$B$2:$G$95,,MATCH(D$1,timeseries!$B$1:$G$1,0)))*4 -> 0.0014794865 | E4: =_xlfn.COVARIANCE.S(INDEX(timeseries!$B$2:$G$95,,MATCH($A4,timeseries!$B$1:$G$1,0)),INDEX(timeseries!$B$2:$G$95,,MATCH(E$1,timeseries!$B$1:$G$1,0)))*4 -> -0.0011387075 | F4: =_xlfn.COVARIANCE.S(INDEX(timeseries!$B$2:$G$95,,MATCH($A4,timeseries!$B$1:$G$1,0)),INDEX(timeseries!$B$2:$G$95,,MATCH(F$1,timeseries!$B$1:$G$1,0)))*4 -> -0.0011510912 | G4: =_xlfn.COVARIANCE.S(INDEX(timeseries!$B$2:$G$95,,MATCH($A4,timeseries!$B$1:$G$1,0)),INDEX(timeseries!$B$2:$G$95,,MATCH(G$1,timeseries!$B$1:$G$1,0)))*4 -> -0.0012507521
A5: World EquityU | B5: =_xlfn.COVARIANCE.S(INDEX(timeseries!$B$2:$G$95,,MATCH($A5,timeseries!$B$1:$G$1,0)),INDEX(timeseries!$B$2:$G$95,,MATCH(B$1,timeseries!$B$1:$G$1,0)))*4 -> -0.0002691238 | C5: =_xlfn.COVARIANCE.S(INDEX(timeseries!$B$2:$G$95,,MATCH($A5,timeseries!$B$1:$G$1,0)),INDEX(timeseries!$B$2:$G$95,,MATCH(C$1,timeseries!$B$1:$G$1,0)))*4 -> 0.00013365517 | D5: =_xlfn.COVARIANCE.S(INDEX(timeseries!$B$2:$G$95,,MATCH($A5,timeseries!$B$1:$G$1,0)),INDEX(timeseries!$B$2:$G$95,,MATCH(D$1,timeseries!$B$1:$G$1,0)))*4 -> -0.0011387075 | E5: =_xlfn.COVARIANCE.S(INDEX(timeseries!$B$2:$G$95,,MATCH($A5,timeseries!$B$1:$G$1,0)),INDEX(timeseries!$B$2:$G$95,,MATCH(E$1,timeseries!$B$1:$G$1,0)))*4 -> 0.021030348 | F5: =_xlfn.COVARIANCE.S(INDEX(timeseries!$B$2:$G$95,,MATCH($A5,timeseries!$B$1:$G$1,0)),INDEX(timeseries!$B$2:$G$95,,MATCH(F$1,timeseries!$B$1:$G$1,0)))*4 -> 0.0076397242 | G5: =_xlfn.COVARIANCE.S(INDEX(timeseries!$B$2:$G$95,,MATCH($A5,timeseries!$B$1:$G$1,0)),INDEX(timeseries!$B$2:$G$95,,MATCH(G$1,timeseries!$B$1:$G$1,0)))*4 -> 0.0064384986
A6: Global Private DebtH | B6: =_xlfn.COVARIANCE.S(INDEX(timeseries!$B$2:$G$95,,MATCH($A6,timeseries!$B$1:$G$1,0)),INDEX(timeseries!$B$2:$G$95,,MATCH(B$1,timeseries!$B$1:$G$1,0)))*4 -> -0.00014418609 | C6: =_xlfn.COVARIANCE.S(INDEX(timeseries!$B$2:$G$95,,MATCH($A6,timeseries!$B$1:$G$1,0)),INDEX(timeseries!$B$2:$G$95,,MATCH(C$1,timeseries!$B$1:$G$1,0)))*4 -> -0.00073218725 | D6: =_xlfn.COVARIANCE.S(INDEX(timeseries!$B$2:$G$95,,MATCH($A6,timeseries!$B$1:$G$1,0)),INDEX(timeseries!$B$2:$G$95,,MATCH(D$1,timeseries!$B$1:$G$1,0)))*4 -> -0.0011510912 | E6: =_xlfn.COVARIANCE.S(INDEX(timeseries!$B$2:$G$95,,MATCH($A6,timeseries!$B$1:$G$1,0)),INDEX(timeseries!$B$2:$G$95,,MATCH(E$1,timeseries!$B$1:$G$1,0)))*4 -> 0.0076397242 | F6: =_xlfn.COVARIANCE.S(INDEX(timeseries!$B$2:$G$95,,MATCH($A6,timeseries!$B$1:$G$1,0)),INDEX(timeseries!$B$2:$G$95,,MATCH(F$1,timeseries!$B$1:$G$1,0)))*4 -> 0.0077082644 | G6: =_xlfn.COVARIANCE.S(INDEX(timeseries!$B$2:$G$95,,MATCH($A6,timeseries!$B$1:$G$1,0)),INDEX(timeseries!$B$2:$G$95,,MATCH(G$1,timeseries!$B$1:$G$1,0)))*4 -> 0.0047306526
A7: EU Private CreditH | B7: =_xlfn.COVARIANCE.S(INDEX(timeseries!$B$2:$G$95,,MATCH($A7,timeseries!$B$1:$G$1,0)),INDEX(timeseries!$B$2:$G$95,,MATCH(B$1,timeseries!$B$1:$G$1,0)))*4 -> -0.00026665598 | C7: =_xlfn.COVARIANCE.S(INDEX(timeseries!$B$2:$G$95,,MATCH($A7,timeseries!$B$1:$G$1,0)),INDEX(timeseries!$B$2:$G$95,,MATCH(C$1,timeseries!$B$1:$G$1,0)))*4 -> -0.00095990114 | D7: =_xlfn.COVARIANCE.S(INDEX(timeseries!$B$2:$G$95,,MATCH($A7,timeseries!$B$1:$G$1,0)),INDEX(timeseries!$B$2:$G$95,,MATCH(D$1,timeseries!$B$1:$G$1,0)))*4 -> -0.0012507521 | E7: =_xlfn.COVARIANCE.S(INDEX(timeseries!$B$2:$G$95,,MATCH($A7,timeseries!$B$1:$G$1,0)),INDEX(timeseries!$B$2:$G$95,,MATCH(E$1,timeseries!$B$1:$G$1,0)))*4 -> 0.0064384986 | F7: =_xlfn.COVARIANCE.S(INDEX(timeseries!$B$2:$G$95,,MATCH($A7,timeseries!$B$1:$G$1,0)),INDEX(timeseries!$B$2:$G$95,,MATCH(F$1,timeseries!$B$1:$G$1,0)))*4 -> 0.0047306526 | G7: =_xlfn.COVARIANCE.S(INDEX(timeseries!$B$2:$G$95,,MATCH($A7,timeseries!$B$1:$G$1,0)),INDEX(timeseries!$B$2:$G$95,,MATCH(G$1,timeseries!$B$1:$G$1,0)))*4 -> 0.0065720186

Sheet corr
B1: =+asset_config!#REF! -> #REF! | C1: =+asset_config!#REF! -> #REF! | D1: =+asset_config!#REF! -> #REF! | G1: {=TRANSPOSE(F2:F12)} -> EUR Cash | H1: Barclays Global TreasuryH | I1: World EquityU | J1: Global Private DebtH | K1: EU Private CreditH | L1: #REF! | M1: #REF! | N1: #REF! | O1: #REF! | P1: #REF! | Q1: #REF!
A2: =+asset_config!#REF! -> #REF! | B2: =+asset_config!#REF! -> #REF! | C2: =+asset_config!#REF! -> #REF! | F2: =cov!A2 -> EUR Cash | G2: =CORREL(INDEX(timeseries!$C$21:$G$92,,MATCH(cov!$A2,timeseries!$C$1:$G$1,0)),INDEX(timeseries!$C$21:$G$92,,MATCH(cov!B$1,timeseries!$C$1:$G$1,0))) -> #N/A | H2: =CORREL(INDEX(timeseries!$C$21:$G$92,,MATCH(cov!$A2,timeseries!$C$1:$G$1,0)),INDEX(timeseries!$C$21:$G$92,,MATCH(cov!C$1,timeseries!$C$1:$G$1,0))) -> #N/A | I2: =CORREL(INDEX(timeseries!$C$21:$G$92,,MATCH(cov!$A2,timeseries!$C$1:$G$1,0)),INDEX(timeseries!$C$21:$G$92,,MATCH(cov!D$1,timeseries!$C$1:$G$1,0))) -> #N/A | J2: =CORREL(INDEX(timeseries!$C$21:$G$92,,MATCH(cov!$A2,timeseries!$C$1:$G$1,0)),INDEX(timeseries!$C$21:$G$92,,MATCH(cov!E$1,timeseries!$C$1:$G$1,0))) -> #N/A | K2: =CORREL(INDEX(timeseries!$C$21:$G$92,,MATCH(cov!$A2,timeseries!$C$1:$G$1,0)),INDEX(timeseries!$C$21:$G$92,,MATCH(cov!F$1,timeseries!$C$1:$G$1,0))) -> #N/A | L2: =CORREL(INDEX(timeseries!$C$21:$G$92,,MATCH(cov!$A2,timeseries!$C$1:$G$1,0)),INDEX(timeseries!$C$21:$G$92,,MATCH(cov!#REF!,timeseries!$C$1:$G$1,0))) -> #N/A | M2: =CORREL(INDEX(timeseries!$C$21:$G$92,,MATCH(cov!$A2,timeseries!$C$1:$G$1,0)),INDEX(timeseries!$C$21:$G$92,,MATCH(cov!#REF!,timeseries!$C$1:$G$1,0))) -> #N/A | N2: =CORREL(INDEX(timeseries!$C$21:$G$92,,MATCH(cov!$A2,timeseries!$C$1:$G$1,0)),INDEX(timeseries!$C$21:$G$92,,MATCH(cov!#REF!,timeseries!$C$1:$G$1,0))) -> #N/A | O2: =CORREL(INDEX(timeseries!$C$21:$G$92,,MATCH(cov!$A2,timeseries!$C$1:$G$1,0)),INDEX(timeseries!$C$21:$G$92,,MATCH(cov!#REF!,timeseries!$C$1:$G$1,0))) -> #N/A | P2: =CORREL(INDEX(timeseries!$C$21:$G$92,,MATCH(cov!$A2,timeseries!$C$1:$G$1,0)),INDEX(timeseries!$C$21:$G$92,,MATCH(cov!#REF!,timeseries!$C$1:$G$1,0))) -> #N/A | Q2: =CORREL(INDEX(timeseries!$C$21:$G$92,,MATCH(cov!$A2,timeseries!$C$1:$G$1,0)),INDEX(timeseries!$C$21:$G$92,,MATCH(cov!#REF!,timeseries!$C$1:$G$1,0))) -> #N/A
A3: =+asset_config!#REF! -> #REF! | B3: =+asset_config!#REF! -> #REF! | C3: =+asset_config!#REF! -> #REF! | D3: =+asset_config!#REF! -> #REF! | F3: =cov!A4 -> Barclays Global TreasuryH | G3: =CORREL(INDEX(timeseries!$C$21:$G$92,,MATCH(cov!$A4,timeseries!$C$1:$G$1,0)),INDEX(timeseries!$C$21:$G$92,,MATCH(cov!B$1,timeseries!$C$1:$G$1,0))) -> #N/A | H3: =CORREL(INDEX(timeseries!$C$21:$G$92,,MATCH(cov!$A4,timeseries!$C$1:$G$1,0)),INDEX(timeseries!$C$21:$G$92,,MATCH(cov!C$1,timeseries!$C$1:$G$1,0))) -> 0.88955799 | I3: =CORREL(INDEX(timeseries!$C$21:$G$92,,MATCH(cov!$A4,timeseries!$C$1:$G$1,0)),INDEX(timeseries!$C$21:$G$92,,MATCH(cov!D$1,timeseries!$C$1:$G$1,0))) -> 1 | J3: =CORREL(INDEX(timeseries!$C$21:$G$92,,MATCH(cov!$A4,timeseries!$C$1:$G$1,0)),INDEX(timeseries!$C$21:$G$92,,MATCH(cov!E$1,timeseries!$C$1:$G$1,0))) -> -0.23243385 | K3: =CORREL(INDEX(timeseries!$C$21:$G$92,,MATCH(cov!$A4,timeseries!$C$1:$G$1,0)),INDEX(timeseries!$C$21:$G$92,,MATCH(cov!F$1,timeseries!$C$1:$G$1,0))) -> -0.3491678 | L3: =CORREL(INDEX(timeseries!$C$21:$G$92,,MATCH(cov!$A4,timeseries!$C$1:$G$1,0)),INDEX(timeseries!$C$21:$G$92,,MATCH(cov!#REF!,timeseries!$C$1:$G$1,0))) -> #REF! | M3: =CORREL(INDEX(timeseries!$C$21:$G$92,,MATCH(cov!$A4,timeseries!$C$1:$G$1,0)),INDEX(timeseries!$C$21:$G$92,,MATCH(cov!#REF!,timeseries!$C$1:$G$1,0))) -> #REF! | N3: =CORREL(INDEX(timeseries!$C$21:$G$92,,MATCH(cov!$A4,timeseries!$C$1:$G$1,0)),INDEX(timeseries!$C$21:$G$92,,MATCH(cov!#REF!,timeseries!$C$1:$G$1,0))) -> #REF! | O3: =CORREL(INDEX(timeseries!$C$21:$G$92,,MATCH(cov!$A4,timeseries!$C$1:$G$1,0)),INDEX(timeseries!$C$21:$G$92,,MATCH(cov!#REF!,timeseries!$C$1:$G$1,0))) -> #REF! | P3: =CORREL(INDEX(timeseries!$C$21:$G$92,,MATCH(cov!$A4,timeseries!$C$1:$G$1,0)),INDEX(timeseries!$C$21:$G$92,,MATCH(cov!#REF!,timeseries!$C$1:$G$1,0))) -> #REF! | Q3: =CORREL(INDEX(timeseries!$C$21:$G$92,,MATCH(cov!$A4,timeseries!$C$1:$G$1,0)),INDEX(timeseries!$C$21:$G$92,,MATCH(cov!#REF!,timeseries!$C$1:$G$1,0))) -> #REF!
A4: =+asset_config!#REF! -> #REF! | B4: =+asset_config!#REF! -> #REF! | C4: =+asset_config!#REF! -> #REF! | D4: =+asset_config!#REF! -> #REF! | F4: =cov!A5 -> World EquityU | G4: =CORREL(INDEX(timeseries!$C$21:$G$92,,MATCH(cov!$A5,timeseries!$C$1:$G$1,0)),INDEX(timeseries!$C$21:$G$92,,MATCH(cov!B$1,timeseries!$C$1:$G$1,0))) -> #N/A | H4: =CORREL(INDEX(timeseries!$C$21:$G$92,,MATCH(cov!$A5,timeseries!$C$1:$G$1,0)),INDEX(timeseries!$C$21:$G$92,,MATCH(cov!C$1,timeseries!$C$1:$G$1,0))) -> 0.0057929023 | I4: =CORREL(INDEX(timeseries!$C$21:$G$92,,MATCH(cov!$A5,timeseries!$C$1:$G$1,0)),INDEX(timeseries!$C$21:$G$92,,MATCH(cov!D$1,timeseries!$C$1:$G$1,0))) -> -0.23243385 | J4: =CORREL(INDEX(timeseries!$C$21:$G$92,,MATCH(cov!$A5,timeseries!$C$1:$G$1,0)),INDEX(timeseries!$C$21:$G$92,,MATCH(cov!E$1,timeseries!$C$1:$G$1,0))) -> 1 | K4: =CORREL(INDEX(timeseries!$C$21:$G$92,,MATCH(cov!$A5,timeseries!$C$1:$G$1,0)),INDEX(timeseries!$C$21:$G$92,,MATCH(cov!F$1,timeseries!$C$1:$G$1,0))) -> 0.6868123 | L4: =CORREL(INDEX(timeseries!$C$21:$G$92,,MATCH(cov!$A5,timeseries!$C$1:$G$1,0)),INDEX(timeseries!$C$21:$G$92,,MATCH(cov!#REF!,timeseries!$C$1:$G$1,0))) -> #REF! | M4: =CORREL(INDEX(timeseries!$C$21:$G$92,,MATCH(cov!$A5,timeseries!$C$1:$G$1,0)),INDEX(timeseries!$C$21:$G$92,,MATCH(cov!#REF!,timeseries!$C$1:$G$1,0))) -> #REF! | N4: =CORREL(INDEX(timeseries!$C$21:$G$92,,MATCH(cov!$A5,timeseries!$C$1:$G$1,0)),INDEX(timeseries!$C$21:$G$92,,MATCH(cov!#REF!,timeseries!$C$1:$G$1,0))) -> #REF! | O4: =CORREL(INDEX(timeseries!$C$21:$G$92,,MATCH(cov!$A5,timeseries!$C$1:$G$1,0)),INDEX(timeseries!$C$21:$G$92,,MATCH(cov!#REF!,timeseries!$C$1:$G$1,0))) -> #REF! | P4: =CORREL(INDEX(timeseries!$C$21:$G$92,,MATCH(cov!$A5,timeseries!$C$1:$G$1,0)),INDEX(timeseries!$C$21:$G$92,,MATCH(cov!#REF!,timeseries!$C$1:$G$1,0))) -> #REF! | Q4: =CORREL(INDEX(timeseries!$C$21:$G$92,,MATCH(cov!$A5,timeseries!$C$1:$G$1,0)),INDEX(timeseries!$C$21:$G$92,,MATCH(cov!#REF!,timeseries!$C$1:$G$1,0))) -> #REF!
A5: =+asset_config!#REF! -> #REF! | B5: =+asset_config!#REF! -> #REF! | C5: =+asset_config!#REF! -> #REF! | D5: =+asset_config!#REF! -> #REF! | F5: =cov!A6 -> Global Private DebtH | G5: =CORREL(INDEX(timeseries!$C$21:$G$92,,MATCH(cov!$A6,timeseries!$C$1:$G$1,0)),INDEX(timeseries!$C$21:$G$92,,MATCH(cov!B$1,timeseries!$C$1:$G$1,0))) -> #N/A | H5: =CORREL(INDEX(timeseries!$C$21:$G$92,,MATCH(cov!$A6,timeseries!$C$1:$G$1,0)),INDEX(timeseries!$C$21:$G$92,,MATCH(cov!C$1,timeseries!$C$1:$G$1,0))) -> -0.13762893 | I5: =CORREL(INDEX(timeseries!$C$21:$G$92,,MATCH(cov!$A6,timeseries!$C$1:$G$1,0)),INDEX(timeseries!$C$21:$G$92,,MATCH(cov!D$1,timeseries!$C$1:$G$1,0))) -> -0.3491678 | J5: =CORREL(INDEX(timeseries!$C$21:$G$92,,MATCH(cov!$A6,timeseries!$C$1:$G$1,0)),INDEX(timeseries!$C$21:$G$92,,MATCH(cov!E$1,timeseries!$C$1:$G$1,0))) -> 0.6868123 | K5: =CORREL(INDEX(timeseries!$C$21:$G$92,,MATCH(cov!$A6,timeseries!$C$1:$G$1,0)),INDEX(timeseries!$C$21:$G$92,,MATCH(cov!F$1,timeseries!$C$1:$G$1,0))) -> 1 | L5: =CORREL(INDEX(timeseries!$C$21:$G$92,,MATCH(cov!$A6,timeseries!$C$1:$G$1,0)),INDEX(timeseries!$C$21:$G$92,,MATCH(cov!#REF!,timeseries!$C$1:$G$1,0))) -> #REF! | M5: =CORREL(INDEX(timeseries!$C$21:$G$92,,MATCH(cov!$A6,timeseries!$C$1:$G$1,0)),INDEX(timeseries!$C$21:$G$92,,MATCH(cov!#REF!,timeseries!$C$1:$G$1,0))) -> #REF! | N5: =CORREL(INDEX(timeseries!$C$21:$G$92,,MATCH(cov!$A6,timeseries!$C$1:$G$1,0)),INDEX(timeseries!$C$21:$G$92,,MATCH(cov!#REF!,timeseries!$C$1:$G$1,0))) -> #REF! | O5: =CORREL(INDEX(timeseries!$C$21:$G$92,,MATCH(cov!$A6,timeseries!$C$1:$G$1,0)),INDEX(timeseries!$C$21:$G$92,,MATCH(cov!#REF!,timeseries!$C$1:$G$1,0))) -> #REF! | P5: =CORREL(INDEX(timeseries!$C$21:$G$92,,MATCH(cov!$A6,timeseries!$C$1:$G$1,0)),INDEX(timeseries!$C$21:$G$92,,MATCH(cov!#REF!,timeseries!$C$1:$G$1,0))) -> #REF! | Q5: =CORREL(INDEX(timeseries!$C$21:$G$92,,MATCH(cov!$A6,timeseries!$C$1:$G$1,0)),INDEX(timeseries!$C$21:$G$92,,MATCH(cov!#REF!,timeseries!$C$1:$G$1,0))) -> #REF!
A6: =+asset_config!#REF! -> #REF! | B6: =+asset_config!#REF! -> #REF! | C6: =+asset_config!#REF! -> #REF! | D6: =+asset_config!#REF! -> #REF! | F6: =cov!A7 -> EU Private CreditH | G6: =CORREL(INDEX(timeseries!$C$21:$G$92,,MATCH(cov!$A7,timeseries!$C$1:$G$1,0)),INDEX(timeseries!$C$21:$G$92,,MATCH(cov!B$1,timeseries!$C$1:$G$1,0))) -> #N/A | H6: =CORREL(INDEX(timeseries!$C$21:$G$92,,MATCH(cov!$A7,timeseries!$C$1:$G$1,0)),INDEX(timeseries!$C$21:$G$92,,MATCH(cov!C$1,timeseries!$C$1:$G$1,0))) -> -0.2401475 | I6: =CORREL(INDEX(timeseries!$C$21:$G$92,,MATCH(cov!$A7,timeseries!$C$1:$G$1,0)),INDEX(timeseries!$C$21:$G$92,,MATCH(cov!D$1,timeseries!$C$1:$G$1,0))) -> -0.40343117 | J6: =CORREL(INDEX(timeseries!$C$21:$G$92,,MATCH(cov!$A7,timeseries!$C$1:$G$1,0)),INDEX(timeseries!$C$21:$G$92,,MATCH(cov!E$1,timeseries!$C$1:$G$1,0))) -> 0.56243789 | K6: =CORREL(INDEX(timeseries!$C$21:$G$92,,MATCH(cov!$A7,timeseries!$C$1:$G$1,0)),INDEX(timeseries!$C$21:$G$92,,MATCH(cov!F$1,timeseries!$C$1:$G$1,0))) -> 0.68463175 | L6: =CORREL(INDEX(timeseries!$C$21:$G$92,,MATCH(cov!$A7,timeseries!$C$1:$G$1,0)),INDEX(timeseries!$C$21:$G$92,,MATCH(cov!#REF!,timeseries!$C$1:$G$1,0))) -> #REF! | M6: =CORREL(INDEX(timeseries!$C$21:$G$92,,MATCH(cov!$A7,timeseries!$C$1:$G$1,0)),INDEX(timeseries!$C$21:$G$92,,MATCH(cov!#REF!,timeseries!$C$1:$G$1,0))) -> #REF! | N6: =CORREL(INDEX(timeseries!$C$21:$G$92,,MATCH(cov!$A7,timeseries!$C$1:$G$1,0)),INDEX(timeseries!$C$21:$G$92,,MATCH(cov!#REF!,timeseries!$C$1:$G$1,0))) -> #REF! | O6: =CORREL(INDEX(timeseries!$C$21:$G$92,,MATCH(cov!$A7,timeseries!$C$1:$G$1,0)),INDEX(timeseries!$C$21:$G$92,,MATCH(cov!#REF!,timeseries!$C$1:$G$1,0))) -> #REF! | P6: =CORREL(INDEX(timeseries!$C$21:$G$92,,MATCH(cov!$A7,timeseries!$C$1:$G$1,0)),INDEX(timeseries!$C$21:$G$92,,MATCH(cov!#REF!,timeseries!$C$1:$G$1,0))) -> #REF! | Q6: =CORREL(INDEX(timeseries!$C$21:$G$92,,MATCH(cov!$A7,timeseries!$C$1:$G$1,0)),INDEX(timeseries!$C$21:$G$92,,MATCH(cov!#REF!,timeseries!$C$1:$G$1,0))) -> #REF!
A7: =+asset_config!#REF! -> #REF! | B7: =+asset_config!#REF! -> #REF! | C7: =+asset_config!#REF! -> #REF! | D7: =+asset_config!#REF! -> #REF! | F7: =cov!#REF! -> #REF! | G7: =CORREL(INDEX(timeseries!$C$21:$G$92,,MATCH(cov!#REF!,timeseries!$C$1:$G$1,0)),INDEX(timeseries!$C$21:$G$92,,MATCH(cov!B$1,timeseries!$C$1:$G$1,0))) -> #REF! | H7: =CORREL(INDEX(timeseries!$C$21:$G$92,,MATCH(cov!#REF!,timeseries!$C$1:$G$1,0)),INDEX(timeseries!$C$21:$G$92,,MATCH(cov!C$1,timeseries!$C$1:$G$1,0))) -> #REF! | I7: =CORREL(INDEX(timeseries!$C$21:$G$92,,MATCH(cov!#REF!,timeseries!$C$1:$G$1,0)),INDEX(timeseries!$C$21:$G$92,,MATCH(cov!D$1,timeseries!$C$1:$G$1,0))) -> #REF! | J7: =CORREL(INDEX(timeseries!$C$21:$G$92,,MATCH(cov!#REF!,timeseries!$C$1:$G$1,0)),INDEX(timeseries!$C$21:$G$92,,MATCH(cov!E$1,timeseries!$C$1:$G$1,0))) -> #REF! | K7: =CORREL(INDEX(timeseries!$C$21:$G$92,,MATCH(cov!#REF!,timeseries!$C$1:$G$1,0)),INDEX(timeseries!$C$21:$G$92,,MATCH(cov!F$1,timeseries!$C$1:$G$1,0))) -> #REF! | L7: =CORREL(INDEX(timeseries!$C$21:$G$92,,MATCH(cov!#REF!,timeseries!$C$1:$G$1,0)),INDEX(timeseries!$C$21:$G$92,,MATCH(cov!#REF!,timeseries!$C$1:$G$1,0))) -> #REF! | M7: =CORREL(INDEX(timeseries!$C$21:$G$92,,MATCH(cov!#REF!,timeseries!$C$1:$G$1,0)),INDEX(timeseries!$C$21:$G$92,,MATCH(cov!#REF!,timeseries!$C$1:$G$1,0))) -> #REF! | N7: =CORREL(INDEX(timeseries!$C$21:$G$92,,MATCH(cov!#REF!,timeseries!$C$1:$G$1,0)),INDEX(timeseries!$C$21:$G$92,,MATCH(cov!#REF!,timeseries!$C$1:$G$1,0))) -> #REF! | O7: =CORREL(INDEX(timeseries!$C$21:$G$92,,MATCH(cov!#REF!,timeseries!$C$1:$G$1,0)),INDEX(timeseries!$C$21:$G$92,,MATCH(cov!#REF!,timeseries!$C$1:$G$1,0))) -> #REF! | P7: =CORREL(INDEX(timeseries!$C$21:$G$92,,MATCH(cov!#REF!,timeseries!$C$1:$G$1,0)),INDEX(timeseries!$C$21:$G$92,,MATCH(cov!#REF!,timeseries!$C$1:$G$1,0))) -> #REF! | Q7: =CORREL(INDEX(timeseries!$C$21:$G$92,,MATCH(cov!#REF!,timeseries!$C$1:$G$1,0)),INDEX(timeseries!$C$21:$G$92,,MATCH(cov!#REF!,timeseries!$C$1:$G$1,0))) -> #REF!
A8: =+asset_config!#REF! -> #REF! | B8: =+asset_config!#REF! -> #REF! | C8: =+asset_config!#REF! -> #REF! | D8: =+asset_config!#REF! -> #REF! | F8: =cov!#REF! -> #REF! | G8: =CORREL(INDEX(timeseries!$C$21:$G$92,,MATCH(cov!#REF!,timeseries!$C$1:$G$1,0)),INDEX(timeseries!$C$21:$G$92,,MATCH(cov!B$1,timeseries!$C$1:$G$1,0))) -> #REF! | H8: =CORREL(INDEX(timeseries!$C$21:$G$92,,MATCH(cov!#REF!,timeseries!$C$1:$G$1,0)),INDEX(timeseries!$C$21:$G$92,,MATCH(cov!C$1,timeseries!$C$1:$G$1,0))) -> #REF! | I8: =CORREL(INDEX(timeseries!$C$21:$G$92,,MATCH(cov!#REF!,timeseries!$C$1:$G$1,0)),INDEX(timeseries!$C$21:$G$92,,MATCH(cov!D$1,timeseries!$C$1:$G$1,0))) -> #REF! | J8: =CORREL(INDEX(timeseries!$C$21:$G$92,,MATCH(cov!#REF!,timeseries!$C$1:$G$1,0)),INDEX(timeseries!$C$21:$G$92,,MATCH(cov!E$1,timeseries!$C$1:$G$1,0))) -> #REF! | K8: =CORREL(INDEX(timeseries!$C$21:$G$92,,MATCH(cov!#REF!,timeseries!$C$1:$G$1,0)),INDEX(timeseries!$C$21:$G$92,,MATCH(cov!F$1,timeseries!$C$1:$G$1,0))) -> #REF! | L8: =CORREL(INDEX(timeseries!$C$21:$G$92,,MATCH(cov!#REF!,timeseries!$C$1:$G$1,0)),INDEX(timeseries!$C$21:$G$92,,MATCH(cov!#REF!,timeseries!$C$1:$G$1,0))) -> #REF! | M8: =CORREL(INDEX(timeseries!$C$21:$G$92,,MATCH(cov!#REF!,timeseries!$C$1:$G$1,0)),INDEX(timeseries!$C$21:$G$92,,MATCH(cov!#REF!,timeseries!$C$1:$G$1,0))) -> #REF! | N8: =CORREL(INDEX(timeseries!$C$21:$G$92,,MATCH(cov!#REF!,timeseries!$C$1:$G$1,0)),INDEX(timeseries!$C$21:$G$92,,MATCH(cov!#REF!,timeseries!$C$1:$G$1,0))) -> #REF! | O8: =CORREL(INDEX(timeseries!$C$21:$G$92,,MATCH(cov!#REF!,timeseries!$C$1:$G$1,0)),INDEX(timeseries!$C$21:$G$92,,MATCH(cov!#REF!,timeseries!$C$1:$G$1,0))) -> #REF! | P8: =CORREL(INDEX(timeseries!$C$21:$G$92,,MATCH(cov!#REF!,timeseries!$C$1:$G$1,0)),INDEX(timeseries!$C$21:$G$92,,MATCH(cov!#REF!,timeseries!$C$1:$G$1,0))) -> #REF! | Q8: =CORREL(INDEX(timeseries!$C$21:$G$92,,MATCH(cov!#REF!,timeseries!$C$1:$G$1,0)),INDEX(timeseries!$C$21:$G$92,,MATCH(cov!#REF!,timeseries!$C$1:$G$1,0))) -> #REF!
A9: =+asset_config!#REF! -> #REF! | B9: =+asset_config!#REF! -> #REF! | C9: =+asset_config!#REF! -> #REF! | D9: =+asset_config!#REF! -> #REF! | F9: =cov!#REF! -> #REF! | G9: =CORREL(INDEX(timeseries!$C$21:$G$92,,MATCH(cov!#REF!,timeseries!$C$1:$G$1,0)),INDEX(timeseries!$C$21:$G$92,,MATCH(cov!B$1,timeseries!$C$1:$G$1,0))) -> #REF! | H9: =CORREL(INDEX(timeseries!$C$21:$G$92,,MATCH(cov!#REF!,timeseries!$C$1:$G$1,0)),INDEX(timeseries!$C$21:$G$92,,MATCH(cov!C$1,timeseries!$C$1:$G$1,0))) -> #REF! | I9: =CORREL(INDEX(timeseries!$C$21:$G$92,,MATCH(cov!#REF!,timeseries!$C$1:$G$1,0)),INDEX(timeseries!$C$21:$G$92,,MATCH(cov!D$1,timeseries!$C$1:$G$1,0))) -> #REF! | J9: =CORREL(INDEX(timeseries!$C$21:$G$92,,MATCH(cov!#REF!,timeseries!$C$1:$G$1,0)),INDEX(timeseries!$C$21:$G$92,,MATCH(cov!E$1,timeseries!$C$1:$G$1,0))) -> #REF! | K9: =CORREL(INDEX(timeseries!$C$21:$G$92,,MATCH(cov!#REF!,timeseries!$C$1:$G$1,0)),INDEX(timeseries!$C$21:$G$92,,MATCH(cov!F$1,timeseries!$C$1:$G$1,0))) -> #REF! | L9: =CORREL(INDEX(timeseries!$C$21:$G$92,,MATCH(cov!#REF!,timeseries!$C$1:$G$1,0)),INDEX(timeseries!$C$21:$G$92,,MATCH(cov!#REF!,timeseries!$C$1:$G$1,0))) -> #REF! | M9: =CORREL(INDEX(timeseries!$C$21:$G$92,,MATCH(cov!#REF!,timeseries!$C$1:$G$1,0)),INDEX(timeseries!$C$21:$G$92,,MATCH(cov!#REF!,timeseries!$C$1:$G$1,0))) -> #REF! | N9: =CORREL(INDEX(timeseries!$C$21:$G$92,,MATCH(cov!#REF!,timeseries!$C$1:$G$1,0)),INDEX(timeseries!$C$21:$G$92,,MATCH(cov!#REF!,timeseries!$C$1:$G$1,0))) -> #REF! | O9: =CORREL(INDEX(timeseries!$C$21:$G$92,,MATCH(cov!#REF!,timeseries!$C$1:$G$1,0)),INDEX(timeseries!$C$21:$G$92,,MATCH(cov!#REF!,timeseries!$C$1:$G$1,0))) -> #REF! | P9: =CORREL(INDEX(timeseries!$C$21:$G$92,,MATCH(cov!#REF!,timeseries!$C$1:$G$1,0)),INDEX(timeseries!$C$21:$G$92,,MATCH(cov!#REF!,timeseries!$C$1:$G$1,0))) -> #REF! | Q9: =CORREL(INDEX(timeseries!$C$21:$G$92,,MATCH(cov!#REF!,timeseries!$C$1:$G$1,0)),INDEX(timeseries!$C$21:$G$92,,MATCH(cov!#REF!,timeseries!$C$1:$G$1,0))) -> #REF!
A10: =+asset_config!#REF! -> #REF! | B10: =+asset_config!#REF! -> #REF! | C10: =+asset_config!#REF! -> #REF! | D10: =+asset_config!#REF! -> #REF! | F10: =cov!#REF! -> #REF! | G10: =CORREL(INDEX(timeseries!$C$21:$G$92,,MATCH(cov!#REF!,timeseries!$C$1:$G$1,0)),INDEX(timeseries!$C$21:$G$92,,MATCH(cov!B$1,timeseries!$C$1:$G$1,0))) -> #REF! | H10: =CORREL(INDEX(timeseries!$C$21:$G$92,,MATCH(cov!#REF!,timeseries!$C$1:$G$1,0)),INDEX(timeseries!$C$21:$G$92,,MATCH(cov!C$1,timeseries!$C$1:$G$1,0))) -> #REF! | I10: =CORREL(INDEX(timeseries!$C$21:$G$92,,MATCH(cov!#REF!,timeseries!$C$1:$G$1,0)),INDEX(timeseries!$C$21:$G$92,,MATCH(cov!D$1,timeseries!$C$1:$G$1,0))) -> #REF! | J10: =CORREL(INDEX(timeseries!$C$21:$G$92,,MATCH(cov!#REF!,timeseries!$C$1:$G$1,0)),INDEX(timeseries!$C$21:$G$92,,MATCH(cov!E$1,timeseries!$C$1:$G$1,0))) -> #REF! | K10: =CORREL(INDEX(timeseries!$C$21:$G$92,,MATCH(cov!#REF!,timeseries!$C$1:$G$1,0)),INDEX(timeseries!$C$21:$G$92,,MATCH(cov!F$1,timeseries!$C$1:$G$1,0))) -> #REF! | L10: =CORREL(INDEX(timeseries!$C$21:$G$92,,MATCH(cov!#REF!,timeseries!$C$1:$G$1,0)),INDEX(timeseries!$C$21:$G$92,,MATCH(cov!#REF!,timeseries!$C$1:$G$1,0))) -> #REF! | M10: =CORREL(INDEX(timeseries!$C$21:$G$92,,MATCH(cov!#REF!,timeseries!$C$1:$G$1,0)),INDEX(timeseries!$C$21:$G$92,,MATCH(cov!#REF!,timeseries!$C$1:$G$1,0))) -> #REF! | N10: =CORREL(INDEX(timeseries!$C$21:$G$92,,MATCH(cov!#REF!,timeseries!$C$1:$G$1,0)),INDEX(timeseries!$C$21:$G$92,,MATCH(cov!#REF!,timeseries!$C$1:$G$1,0))) -> #REF! | O10: =CORREL(INDEX(timeseries!$C$21:$G$92,,MATCH(cov!#REF!,timeseries!$C$1:$G$1,0)),INDEX(timeseries!$C$21:$G$92,,MATCH(cov!#REF!,timeseries!$C$1:$G$1,0))) -> #REF! | P10: =CORREL(INDEX(timeseries!$C$21:$G$92,,MATCH(cov!#REF!,timeseries!$C$1:$G$1,0)),INDEX(timeseries!$C$21:$G$92,,MATCH(cov!#REF!,timeseries!$C$1:$G$1,0))) -> #REF! | Q10: =CORREL(INDEX(timeseries!$C$21:$G$92,,MATCH(cov!#REF!,timeseries!$C$1:$G$1,0)),INDEX(timeseries!$C$21:$G$92,,MATCH(cov!#REF!,timeseries!$C$1:$G$1,0))) -> #REF!
A11: =+asset_config!#REF! -> #REF! | B11: =+asset_config!#REF! -> #REF! | C11: =+asset_config!#REF! -> #REF! | D11: =+asset_config!#REF! -> #REF! | F11: =cov!#REF! -> #REF! | G11: =CORREL(INDEX(timeseries!$C$21:$G$92,,MATCH(cov!#REF!,timeseries!$C$1:$G$1,0)),INDEX(timeseries!$C$21:$G$92,,MATCH(cov!B$1,timeseries!$C$1:$G$1,0))) -> #REF! | H11: =CORREL(INDEX(timeseries!$C$21:$G$92,,MATCH(cov!#REF!,timeseries!$C$1:$G$1,0)),INDEX(timeseries!$C$21:$G$92,,MATCH(cov!C$1,timeseries!$C$1:$G$1,0))) -> #REF! | I11: =CORREL(INDEX(timeseries!$C$21:$G$92,,MATCH(cov!#REF!,timeseries!$C$1:$G$1,0)),INDEX(timeseries!$C$21:$G$92,,MATCH(cov!D$1,timeseries!$C$1:$G$1,0))) -> #REF! | J11: =CORREL(INDEX(timeseries!$C$21:$G$92,,MATCH(cov!#REF!,timeseries!$C$1:$G$1,0)),INDEX(timeseries!$C$21:$G$92,,MATCH(cov!E$1,timeseries!$C$1:$G$1,0))) -> #REF! | K11: =CORREL(INDEX(timeseries!$C$21:$G$92,,MATCH(cov!#REF!,timeseries!$C$1:$G$1,0)),INDEX(timeseries!$C$21:$G$92,,MATCH(cov!F$1,timeseries!$C$1:$G$1,0))) -> #REF! | L11: =CORREL(INDEX(timeseries!$C$21:$G$92,,MATCH(cov!#REF!,timeseries!$C$1:$G$1,0)),INDEX(timeseries!$C$21:$G$92,,MATCH(cov!#REF!,timeseries!$C$1:$G$1,0))) -> #REF! | M11: =CORREL(INDEX(timeseries!$C$21:$G$92,,MATCH(cov!#REF!,timeseries!$C$1:$G$1,0)),INDEX(timeseries!$C$21:$G$92,,MATCH(cov!#REF!,timeseries!$C$1:$G$1,0))) -> #REF! | N11: =CORREL(INDEX(timeseries!$C$21:$G$92,,MATCH(cov!#REF!,timeseries!$C$1:$G$1,0)),INDEX(timeseries!$C$21:$G$92,,MATCH(cov!#REF!,timeseries!$C$1:$G$1,0))) -> #REF! | O11: =CORREL(INDEX(timeseries!$C$21:$G$92,,MATCH(cov!#REF!,timeseries!$C$1:$G$1,0)),INDEX(timeseries!$C$21:$G$92,,MATCH(cov!#REF!,timeseries!$C$1:$G$1,0))) -> #REF! | P11: =CORREL(INDEX(timeseries!$C$21:$G$92,,MATCH(cov!#REF!,timeseries!$C$1:$G$1,0)),INDEX(timeseries!$C$21:$G$92,,MATCH(cov!#REF!,timeseries!$C$1:$G$1,0))) -> #REF! | Q11: =CORREL(INDEX(timeseries!$C$21:$G$92,,MATCH(cov!#REF!,timeseries!$C$1:$G$1,0)),INDEX(timeseries!$C$21:$G$92,,MATCH(cov!#REF!,timeseries!$C$1:$G$1,0))) -> #REF!
A12: =+asset_config!#REF! -> #REF! | B12: =+asset_config!#REF! -> #REF! | C12: =+asset_config!#REF! -> #REF! | D12: =+asset_config!#REF! -> #REF! | F12: =cov!#REF! -> #REF! | G12: =CORREL(INDEX(timeseries!$C$21:$G$92,,MATCH(cov!#REF!,timeseries!$C$1:$G$1,0)),INDEX(timeseries!$C$21:$G$92,,MATCH(cov!B$1,timeseries!$C$1:$G$1,0))) -> #REF! | H12: =CORREL(INDEX(timeseries!$C$21:$G$92,,MATCH(cov!#REF!,timeseries!$C$1:$G$1,0)),INDEX(timeseries!$C$21:$G$92,,MATCH(cov!C$1,timeseries!$C$1:$G$1,0))) -> #REF! | I12: =CORREL(INDEX(timeseries!$C$21:$G$92,,MATCH(cov!#REF!,timeseries!$C$1:$G$1,0)),INDEX(timeseries!$C$21:$G$92,,MATCH(cov!D$1,timeseries!$C$1:$G$1,0))) -> #REF! | J12: =CORREL(INDEX(timeseries!$C$21:$G$92,,MATCH(cov!#REF!,timeseries!$C$1:$G$1,0)),INDEX(timeseries!$C$21:$G$92,,MATCH(cov!E$1,timeseries!$C$1:$G$1,0))) -> #REF! | K12: =CORREL(INDEX(timeseries!$C$21:$G$92,,MATCH(cov!#REF!,timeseries!$C$1:$G$1,0)),INDEX(timeseries!$C$21:$G$92,,MATCH(cov!F$1,timeseries!$C$1:$G$1,0))) -> #REF! | L12: =CORREL(INDEX(timeseries!$C$21:$G$92,,MATCH(cov!#REF!,timeseries!$C$1:$G$1,0)),INDEX(timeseries!$C$21:$G$92,,MATCH(cov!#REF!,timeseries!$C$1:$G$1,0))) -> #REF! | M12: =CORREL(INDEX(timeseries!$C$21:$G$92,,MATCH(cov!#REF!,timeseries!$C$1:$G$1,0)),INDEX(timeseries!$C$21:$G$92,,MATCH(cov!#REF!,timeseries!$C$1:$G$1,0))) -> #REF! | N12: =CORREL(INDEX(timeseries!$C$21:$G$92,,MATCH(cov!#REF!,timeseries!$C$1:$G$1,0)),INDEX(timeseries!$C$21:$G$92,,MATCH(cov!#REF!,timeseries!$C$1:$G$1,0))) -> #REF! | O12: =CORREL(INDEX(timeseries!$C$21:$G$92,,MATCH(cov!#REF!,timeseries!$C$1:$G$1,0)),INDEX(timeseries!$C$21:$G$92,,MATCH(cov!#REF!,timeseries!$C$1:$G$1,0))) -> #REF! | P12: =CORREL(INDEX(timeseries!$C$21:$G$92,,MATCH(cov!#REF!,timeseries!$C$1:$G$1,0)),INDEX(timeseries!$C$21:$G$92,,MATCH(cov!#REF!,timeseries!$C$1:$G$1,0))) -> #REF! | Q12: =CORREL(INDEX(timeseries!$C$21:$G$92,,MATCH(cov!#REF!,timeseries!$C$1:$G$1,0)),INDEX(timeseries!$C$21:$G$92,,MATCH(cov!#REF!,timeseries!$C$1:$G$1,0))) -> #REF!

Sheet Sheet1
A1: Start Date | B1: 40574 | J1: Start Date | K1: 40574 | T1: Start Date | U1: 40574
A2: End Date | J2: End Date | T2: End Date
B4: NDUEACWF Index | C4: LEGATRUH Index | D4: LG30TRUH Index | E4: XBTUSD Curncy | F4: XAU Curncy | G4: G0O1 Index | K4: NDEEWNR Index | L4: LEGATREH Index | M4: LG30TREH Index | N4: XBTEUR Curncy | O4: XAUEUR Curncy | P4: G0DB Index | Q4: USDEUR Index | T4: Start Date | U4: =J7 -> #NAME?
B5: =_xll.BFieldInfo(B$6) -> #NAME? | C5: =_xll.BFieldInfo(C$6) -> #NAME? | D5: =_xll.BFieldInfo(D$6) -> #NAME? | E5: =_xll.BFieldInfo(E$6) -> #NAME? | F5: =_xll.BFieldInfo(F$6) -> #NAME? | G5: =_xll.BFieldInfo(G$6) -> #NAME? | K5: =_xll.BFieldInfo(K$6) -> #NAME? | L5: =_xll.BFieldInfo(L$6) -> #NAME? | M5: =_xll.BFieldInfo(M$6) -> #NAME? | N5: =_xll.BFieldInfo(N$6) -> #NAME? | O5: =_xll.BFieldInfo(O$6) -> #NAME? | P5: =_xll.BFieldInfo(P$6) -> #NAME? | Q5: =_xll.BFieldInfo(Q$6) -> #NAME? | T5: End Date
A6: Dates | B6: PX_LAST | C6: PX_LAST | D6: PX_LAST | E6: PX_LAST | F6: PX_LAST | G6: PX_LAST | J6: Dates | K6: PX_LAST | L6: PX_LAST | M6: PX_LAST | N6: PX_LAST | O6: PX_LAST | P6: PX_LAST | Q6: PX_LAST
A7: =_xll.BDH(B$4,B$6,$B1,$B2,"Dir=V","Per=M","Days=A","Dts=S","cols=2;rows=186") -> #NAME? | B7: 139.1525 | C7: =_xll.BDH(C$4,C$6,$B1,$B2,"Dir=V","Per=M","Days=A","Dts=H","cols=1;rows=186") -> #NAME? | D7: =_xll.BDH(D$4,D$6,$B1,$B2,"Dir=V","Per=M","Days=A","Dts=H","cols=1;rows=186") -> #NAME? | E7: =_xll.BDH(E$4,E$6,$B1,$B2,"Dir=V","Per=M","Days=A","Dts=H","cols=1;rows=186") -> #NAME? | F7: =_xll.BDH(F$4,F$6,$B1,$B2,"Dir=V","Per=M","Days=A","Dts=H","cols=1;rows=186") -> #NAME? | G7: =_xll.BDH(G$4,G$6,$B1,$B2,"Dir=V","Per=M","Days=A","Dts=H","cols=1;rows=186") -> #NAME? | J7: =_xll.BDH(K$4,K$6,$B1,$B2,"Dir=V","Per=M","Days=A","Dts=S","cols=2;rows=186") -> #NAME? | K7: 95.291 | L7: =_xll.BDH(L$4,L$6,$B1,$B2,"Dir=V","Per=M","Days=A","Dts=H","cols=1;rows=186") -> #NAME? | M7: =_xll.BDH(M$4,M$6,$B1,$B2,"Dir=V","Per=M","Days=A","Dts=H","cols=1;rows=186") -> #NAME? | N7: =_xll.BDH(N$4,N$6,$B1,$B2,"Dir=V","Per=M","Days=A","Dts=H","cols=1;rows=186") -> #NAME? | O7: =_xll.BDH(O$4,O$6,$B1,$B2,"Dir=V","Per=M","Days=A","Dts=H","cols=1;rows=186") -> #NAME? | P7: =_xll.BDH(P$4,P$6,$B1,$B2,"Dir=V","Per=M","Days=A","Dts=H","cols=1;rows=186") -> #NAME? | Q7: =_xll.BDH(Q$4,Q$6,$B1,$B2,"Dir=V","Per=M","Days=A","Dts=H","cols=1;rows=186") -> #NAME? | R7: =E7*Q7 -> #NAME? | U7: XBT Curncy
A8: 40602 | B8: 143.2054 | C8: 396.7396 | D8: 287.1984 | E8: 0.86 | F8: 1411.33 | G8: 687.609 | J8: 40602 | K8: 97.342 | L8: 174.6663 | M8: 261.8483 | N8: #N/A N/A | O8: 1022 | P8: 139.686 | Q8: 0.7243 | R8: =E8*Q8 -> 0.622898 | U8: =_xll.BFieldInfo(U$9) -> #NAME?
A9: 40633 | B9: 143.0617 | C9: 396.4389 | D9: 288.5886 | E9: 0.78 | F9: 1432.2 | G9: 687.788 | J9: 40633 | K9: 94.647 | L9: 174.6191 | M9: 263.2285 | N9: #N/A N/A | O9: 1011.68 | P9: 139.733 | Q9: 0.7064 | R9: =E9*Q9 -> 0.550992 | T9: Dates | U9: PX_LAST
A10: 40662 | B10: 148.9146 | C10: 400.0332 | D10: 293.1228 | E10: 2.88 | F10: 1563.7 | G10: 687.926 | J10: 40662 | K10: 94.236 | L10: 176.2445 | M10: 267.3938 | N10: #N/A N/A | O10: 1056.09 | P10: 139.803 | Q10: 0.6753 | R10: =E10*Q10 -> 1.944864 | T10: =_xll.BDH(U$7,U$9,$U4,$U5,"Dir=V","FX=EUR","Dts=S","Per=M","cols=2;rows=186") -> #NAME? | U10: 0.52
A11: 40694 | B11: 145.7144 | C11: 403.9173 | D11: 294.5568 | E11: 8.74 | F11: 1535.73 | G11: 687.974 | J11: 40694 | K11: 95.161 | L11: 178.149 | M11: 268.9243 | N11: #N/A N/A | O11: 1066.8 | P11: 139.946 | Q11: 0.6946 | R11: =E11*Q11 -> 6.070804 | T11: 40602 | U11: 0.86
A12: 40724 | B12: 143.4182 | C12: 403.1152 | D12: 292.3487 | E12: 16.1 | F12: 1500.18 | G12: 688.036 | J12: 40724 | K12: 92.87 | L12: 177.9364 | M12: 267.1415 | N12: #N/A N/A | O12: 1034.55 | P12: 140.035 | Q12: 0.6896 | R12: =E12*Q12 -> 11.10256 | T12: 40633 | U12: 0.78
A13: 40753 | B13: 141.0834 | C13: 407.6459 | D13: 295.3264 | E13: 13.5 | F13: 1627.05 | G13: 687.99 | J13: 40753 | K13: 92.175 | L13: 180.107 | M13: 270.1116 | N13: #N/A N/A | O13: 1130.35 | P13: 140.343 | Q13: 0.6945 | R13: =E13*Q13 -> 9.37575 | T13: 40663 | U13: 2.88
A14: 40786 | B14: 130.7772 | C14: 412.621 | D14: 283.8393 | E14: 8.2 | F14: 1825.55 | G14: 688.145 | J14: 40786 | K14: 85.276 | L14: 182.4223 | M14: 259.8102 | N14: #N/A N/A | O14: 1270.4 | P14: 140.652 | Q14: 0.6957 | R14: =E14*Q14 -> 5.70474 | T14: 40694 | U14: 8.74
A15: 40816 | B15: 118.43 | C15: 415.0849 | D15: 272.8415 | E15: 5.14 | F15: 1623.79 | G15: 688.158 | J15: 40816 | K15: 82.871 | L15: 183.6413 | M15: 248.99 | N15: #N/A N/A | O15: 1212.92 | P15: 140.861 | Q15: 0.7468 | R15: =E15*Q15 -> 3.838552 | T15: 40724 | U15: 16.1
A16: 40847 | B16: 131.1195 | C16: 414.6773 | D16: 289.4138 | E16: 3.25 | F16: 1714.7 | G16: 688.172 | J16: 40847 | K16: 88.257 | L16: 183.5222 | M16: 263.6716 | N16: #N/A N/A | O16: 1237.35 | P16: 140.899 | Q16: 0.7216 | R16: =E16*Q16 -> 2.3452 | T16: 40755 | U16: 13.5
A17: 40877 | B17: 127.1937 | C17: 412.4269 | D17: 282.0403 | E17: 2.97 | F17: 1746.35 | G17: 688.165 | J17: 40877 | K17: 88.709 | L17: 182.5352 | M17: 256.7265 | N17: #N/A N/A | O17: 1298.79 | P17: 141.048 | Q17: 0.7438 | R17: =E17*Q17 -> 2.209086 | T17: 40786 | U17: 8.2
A18: 40907 | B18: 126.9371 | C18: 418.6998 | D18: 289.1168 | E18: 4.25 | F18: 1564.91 | G18: 688.159 | J18: 40907 | K18: 91.804 | L18: 185.3395 | M18: 263.2484 | N18: #N/A N/A | O18: 1206.81 | P18: 141.097 | Q18: 0.7714 | R18: =E18*Q18 -> 3.27845 | T18: 40816 | U18: 5.14
A19: 40939 | B19: 134.3176 | C19: 422.8371 | D19: 299.4476 | E19: 5.48 | F19: 1737.76 | G19: 688.144 | J19: 40939 | K19: 96.333 | L19: 187.1195 | M19: 272.5391 | N19: #N/A N/A | O19: 1328.31 | P19: 141.065 | Q19: 0.7643 | R19: =E19*Q19 -> 4.188364 | T19: 40847 | U19: 3.25
A20: 40968 | B20: 141.0757 | C20: 424.3657 | D20: 308.5365 | E20: 4.86 | F20: 1696.76 | G20: 688.158 | J20: 40968 | K20: 99.012 | L20: 187.7767 | M20: 280.6572 | N20: #N/A N/A | O20: 1273.51 | P20: 141.112 | Q20: 0.7505 | R20: =E20*Q20 -> 3.64743 | T20: 40877 | U20: 2.97
A21: 40998 | B21: 142.0126 | C21: 423.7516 | D21: 308.9902 | E21: 4.86 | F21: 1668.15 | G21: 688.235 | J21: 40998 | K21: 100.119 | L21: 187.4805 | M21: 281.031 | N21: #N/A N/A | O21: 1250.35 | P21: 141.116 | Q21: 0.7495 | R21: =E21*Q21 -> 3.64257 | T21: 40908 | U21: 4.25
A22: 41029 | B22: 140.389 | C22: 426.3925 | D22: 311.7074 | E22: 4.95 | F22: 1664.75 | G22: 688.261 | J22: 41029 | K22: 99.584 | L22: 188.6286 | M22: 283.4687 | N22: #N/A N/A | O22: 1257.49 | P22: 141.151 | Q22: 0.7554 | R22: =E22*Q22 -> 3.73923 | T22: 40939 | U22: 5.48
... A38: 41516 | B38: 160.4028 | C38: 437.5248 | D38: 350.7947 | E38: 126.02 | F38: 1395.27 | G38: 689.288 | J38: 41516 | K38: 114.208 | L38: 193.0391 | M38: 316.781 | N38: #N/A N/A | O38: 1055.25 | P38: 141.305 | Q38: 0.7564 | R38: =E38*Q38 -> 95.321528 | T38: 41425 | U38: 127.2
A39: 41547 | B39: 168.6883 | C39: 441.0758 | D39: 354.9137 | E39: 127.09 | F39: 1329.03 | G39: 689.32 | J39: 41547 | K39: 116.997 | L39: 194.5534 | M39: 320.4173 | N39: 94.5 | O39: 982.57 | P39: 141.326 | Q39: 0.7393 | R39: =E39*Q39 -> 93.957637 | T39: 41455 | U39: 96.99
A40: 41578 | B40: 175.4677 | C40: 445.0392 | D40: 363.5945 | E40: 206.34 | F40: 1323.06 | G40: 689.294 | J40: 41578 | K40: 121.175 | L40: 196.28 | M40: 328.2017 | N40: 150 | O40: 974.03 | P40: 141.33 | Q40: 0.7362 | R40: =E40*Q40 -> 151.90751 | T40: 41486 | U40: 97.25
A41: 41607 | B41: 177.953 | C41: 444.4295 | D41: 364.5839 | E41: 1137 | F41: 1253.35 | G41: 689.335 | J41: 41607 | K41: 122.707 | L41: 196 | M41: 329.0738 | N41: 850.5 | O41: 922.24 | P41: 141.326 | Q41: 0.7358 | R41: =E41*Q41 -> 836.6046 | T41: 41517 | U41: 126.02
A42: 41639 | B42: 181.0234 | C42: 442.0281 | D42: 367.0537 | E42: 746.89 | F42: 1201.64 | G42: 689.425 | J42: 41639 | K42: 123.338 | L42: 194.9594 | M42: 331.2925 | N42: 539 | O42: 875.88 | P42: 141.307 | Q42: 0.7277 | R42: =E42*Q42 -> 543.51185 | T42: 41547 | U42: 127.09
A43: 41670 | B43: 173.7821 | C43: 448.3776 | D43: 367.7831 | E43: 806.69 | F43: 1244.55 | G43: 689.471 | J43: 41670 | K43: 120.986 | L43: 197.8189 | M43: 331.9359 | N43: 595.89 | O43: 922.74 | P43: 141.348 | Q43: 0.7415 | R43: =E43*Q43 -> 598.16064 | T43: 41578 | U43: 206.34
A44: 41698 | B44: 182.1774 | C44: 450.5812 | D44: 375.4909 | E44: 566.91 | F44: 1326.39 | G44: 689.475 | J44: 41698 | K44: 123.837 | L44: 198.7734 | M44: 338.7635 | N44: 409.63 | O44: 961.04 | P44: 141.364 | Q44: 0.7246 | R44: =E44*Q44 -> 410.78299 | T44: 41608 | U44: 1137
A45: 41729 | B45: 182.9872 | C45: 451.0242 | D45: 377.8549 | E45: 465.75 | F45: 1284.01 | G45: 689.504 | J45: 41729 | K45: 124.649 | L45: 198.9725 | M45: 340.905 | N45: 334.13 | O45: 932.46 | P45: 141.363 | Q45: 0.7263 | R45: =E45*Q45 -> 338.27423 | T45: 41639 | U45: 746.89
A46: 41759 | B46: 184.7287 | C46: 454.1452 | D46: 381.0369 | E46: 448.23 | F46: 1291.6 | G46: 689.533 | J46: 41759 | K46: 125.082 | L46: 200.3564 | M46: 343.7893 | N46: 323.66 | O46: 931.35 | P46: 141.393 | Q46: 0.7211 | R46: =E46*Q46 -> 323.21865 | T46: 41670 | U46: 806.69
A47: 41789 | B47: 188.6578 | C47: 458.526 | D47: 385.4803 | E47: 613.92 | F47: 1249.68 | G47: 689.537 | J47: 41789 | K47: 129.802 | L47: 202.3309 | M47: 347.8668 | N47: 445.79 | O47: 916.74 | P47: 141.433 | Q47: 0.7335 | R47: =E47*Q47 -> 450.31032 | T47: 41698 | U47: 566.91
A48: 41820 | B48: 192.2101 | C48: 460.0841 | D48: 389.3064 | E48: 646.97 | F48: 1327.33 | G48: 689.573 | J48: 41820 | K48: 131.802 | L48: 203.0319 | M48: 351.3383 | N48: 470.34 | O48: 969.39 | P48: 141.46 | Q48: 0.7305 | R48: =E48*Q48 -> 472.61159 | T48: 41729 | U48: 465.75
A49: 41851 | B49: 189.8789 | C49: 461.0745 | D49: 385.965 | E49: 586.36 | F49: 1282.59 | G49: 689.593 | J49: 41851 | K49: 133.234 | L49: 203.4488 | M49: 348.1756 | N49: 438.72 | O49: 957.9 | P49: 141.466 | Q49: 0.7466 | R49: =E49*Q49 -> 437.77638 | T49: 41759 | U49: 448.23
A50: 41880 | B50: 194.0735 | C50: 466.693 | D50: 389.4911 | E50: 479.7 | F50: 1287.32 | G50: 689.615 | J50: 41880 | K50: 138.328 | L50: 205.9438 | M50: 351.3588 | N50: 385.79 | O50: 980.44 | P50: 141.475 | Q50: 0.7615 | R50: =E50*Q50 -> 365.29155 | T50: 41790 | U50: 613.92
... A184: 45961 | B184: 552.1455 | C184: 608.4579 | D184: 681.2222 | E184: 109428.01 | F184: 4002.92 | G184: 850.677 | J184: 45961 | K184: 449.126 | L184: 220.4738 | M184: 496.6238 | N184: 94838.83 | O184: 3470.04 | P184: 146.793 | Q184: 0.8668 | R184: =E184*Q184 -> 94852.199 | T184: 45869 | U184: 116491.12
A185: 45989 | B185: 552.0842 | C185: 609.737 | D185: 684.4667 | E185: 91176.49 | F185: 4239.43 | G185: 853.034 | J185: 45989 | K185: 446.619 | L185: 220.5904 | M185: 498.2044 | N185: 78399.59 | O185: 3625.69 | P185: 146.963 | Q185: 0.8622 | T185: 45900 | U185: 109127.01
A186: 46022 | B186: 557.846 | C186: 608.4297 | D186: 689.8205 | E186: 87647.54 | F186: 4319.37 | G186: 856.007 | J186: 46022 | K186: 445.94 | L186: 219.7193 | M186: 501.152 | N186: 74597.78 | O186: 3677.18 | P186: 147.217 | Q186: 0.8514 | T186: 45930 | U186: 114640.81
A187: 46052 | B187: 574.383 | C187: 609.9005 | D187: 695.0141 | E187: 78197.32 | F187: 4894.23 | G187: 858.464 | J187: 46052 | K187: 453.293 | L187: 219.9516 | M187: 504.2212 | N187: 71053.25 | O187: 4120.88 | P187: 147.451 | Q187: 0.8438 | T187: 45961 | U187: 109428.01
A188: 46080 | B188: 581.767 | C188: 618.4738 | D188: 697.7452 | E188: 66723.7 | F188: 5278.93 | G188: 860.78 | J188: 46080 | K188: 462.6 | L188: 222.7694 | M188: 505.5273 | N188: 55485.09 | O188: 4467.43 | P188: 147.692 | Q188: 0.8466 | T188: 45991 | U188: 91176.49
A189: 46112 | B189: 539.9862 | C189: 607.4957 | D189: 683.8213 | E189: 68193.95 | F189: 4668.06 | G189: 863.278 | J189: 46112 | K189: 439.998 | L189: 218.3759 | M189: 494.3882 | N189: 59035.67 | O189: 4041.46 | P189: 147.749 | Q189: 0.8656 | T189: 46022 | U189: 87647.54
...

Sheet SGD mkt cap
N1: Equity Exp | O1: 0 | P1: 0.2 | Q1: 0.5
A2: Global Treasury | B2: 0.0033 | N2: Bond | O2: 0.9 | P2: =1-P1 -> 0.8 | Q2: =1-Q1 -> 0.5
A3: DM Equity | B3: 0.0043 | O3: BMK_CapPres | P3: BMK_Cons | Q3: BMK_Mod
N4: =asset_config!A2 -> EUR Cash | O4: 0.1 | P4: 0 | Q4: 0
C5: No SGD | D5: With SGD | H5: No SGD | I5: With SGD | N5: =asset_config!A4 -> Barclays Global TreasuryH | O5: =$D$10*O$2 -> 0.0022261146 | P5: =$D$10*P$2 -> 0.0019787685 | Q5: =$D$10*Q$2 -> 0.0012367303
A6: Globl Gov | B6: ='[2]Global AGG'!$D$10+'[2]Global AGG'!$D$9 -> 5.038368e+10 | C6: =B6/SUM($B$6:$B$9) -> 0.74953353 | D6: =C6-D10 -> 0.74706007 | G6: DM Equity | H6: =1-H7 -> 0.89719879 | I6: =H6-I8 -> 0.89334083 | N6: =asset_config!A5 -> World EquityU | O6: =$D$6*O$2 -> 0.67235406 | P6: =$D$6*P$2 -> 0.59764805 | Q6: =$D$6*Q$2 -> 0.37353003
A7: Glob IG | B7: ='[2]Global AGG'!$D$15 -> 1.3318203e+10 | C7: =B7/SUM($B$6:$B$9) -> 0.19812843 | D7: =C7 -> 0.19812843 | G7: EM Equity | H7: =[3]instrument!$S$125 -> 0.10280121 | I7: =H7 -> 0.10280121 | N7: =asset_config!A6 -> Global Private DebtH | O7: =$D$7*O$2 -> 0.17831559 | P7: =$D$7*P$2 -> 0.15850275 | Q7: =$D$7*Q$2 -> 0.099064217
A8: Glob HY | B8: ='[2]Global HY'!$O$8/1000 -> 2.7625056e+09 | C8: =B8/SUM($B$6:$B$9) -> 0.041096453 | D8: =C8 -> 0.041096453 | G8: SGD Equity | I8: =B3*H6 -> 0.0038579548 | N8: =asset_config!A7 -> EU Private CreditH | O8: =$D$8*O$2 -> 0.036986808 | P8: =$D$8*P$2 -> 0.032877162 | Q8: =$D$8*Q$2 -> 0.020548226
A9: EMBI | B9: ='[2]Global HY'!$O$9/1000 -> 7.5565999e+08 | C9: =B9/SUM($B$6:$B$9) -> 0.011241587 | D9: =C9 -> 0.011241587 | N9: =asset_config!#REF! -> #REF! | O9: =$D$9*O$2 -> 0.010117428 | P9: =$D$9*P$2 -> 0.0089932692 | Q9: =$D$9*Q$2 -> 0.0056207933
A10: SGD Govt | D10: =B2*C6 -> 0.0024734606 | N10: =asset_config!#REF! -> #REF! | O10: 0 | P10: 0 | Q10: 0
N11: =asset_config!#REF! -> #REF! | O11: =O$1*$I$6 -> 0 | P11: =P$1*$I$6 -> 0.17866817 | Q11: =Q$1*$I$6 -> 0.44667042
A12: total | C12: =SUM(C6:C10) -> 1 | D12: =SUM(D6:D10) -> 1 | H12: =SUM(H6:H10) -> 1 | I12: =SUM(I6:I10) -> 1 | N12: =asset_config!#REF! -> #REF! | O12: =$I$7*O$1 -> 0 | P12: =$I$7*P$1 -> 0.020560242 | Q12: =$I$7*Q$1 -> 0.051400606
N13: =asset_config!#REF! -> #REF! | O13: =$I$8*O$1 -> 0 | P13: =$I$8*P$1 -> 0.00077159096 | Q13: =$I$8*Q$1 -> 0.0019289774
N14: =asset_config!#REF! -> #REF! | O14: 0 | P14: 0 | Q14: 0
N15: =asset_config!#REF! -> #REF! | O15: 0 | P15: 0 | Q15: 0
N16: =asset_config!#REF! -> #REF! | O16: 0 | P16: 0 | Q16: 0
N17: =asset_config!#REF! -> #REF! | O17: 0 | P17: 0 | Q17: 0
N18: =asset_config!#REF! -> #REF! | O18: 0 | P18: 0 | Q18: 0
